from django.test import TestCase
from django.contrib.auth import get_user_model


class ModelTests(TestCase):

    def test_create_user_with_email_successful(self):
        """Test creating a new user with email is successful"""
        email = 'test@workbound.info'
        password = 'testpass123'
        User = get_user_model()
        user = User.objects.create_user(
            email=email,
            password=password,
        )

        self.assertEqual(user.email, email)
        self.assertTrue(user.check_password(password))
        self.assertTrue(user.is_active)
        self.assertFalse(user.is_staff)
        self.assertFalse(user.is_superuser)

    def test_create_superuser(self):
        """Tests that a superuser can be created"""
        User = get_user_model()
        admin_user = User.objects.create_superuser(email='super@user.com', password='foo')
        self.assertEqual(admin_user.email, 'super@user.com')
        self.assertTrue(admin_user.is_active)
        self.assertTrue(admin_user.is_staff)
        self.assertTrue(admin_user.is_superuser)
        try:
            self.assertIsNone(admin_user.username)
        except AttributeError:
            pass
        with self.assertRaises(ValueError):
            User.objects.create_superuser(
                email='super@user.com', password='foo', is_superuser=False)

    def test_new_user_email_normalized(self):
        """Test that user email is normalized"""
        email = 'test@WORKBOUND.INFO'
        user = get_user_model().objects.create_user(email, 'testpass123')

        self.assertEqual(user.email, email.lower())

    def test_new_user_invalid_email(self):
        """Test creating user with no email raises error"""
        with self.assertRaises(ValueError):
            get_user_model().objects.create_user(None, 'testpass123')
